Workbook

Sheet Raw Data
A1: First Name | B1: Last Name | C1: transaction
A2: nooeukw | B2: uuoaklowalb | C2: {'tx_id': '5ed3d67b8723c11444c43283', 'tx_date': '2020-06-13T05:28:47.543000Z', 'tx_amount': 6192, 'tx_mode': 'Debit', 'tx_channel': 'web', 'bank_name': 'QBank', 'dob': ['1992-11-10 00:00:00']}
A3: angulbo | B3: seagn | C3: {'tx_id': '5ed3d67b8723c11444c43283', 'tx_date': '2020-06-12T20:22:38.986000Z', 'tx_amount': 38445, 'tx_mode': 'Debit', 'tx_channel': 'mobile', 'bank_name': 'ABank', 'dob': ['n/a']}
A4: dukowi | B4: eukloomja | C4: {'tx_id': '5ed3d67b8723c11444c43283', 'tx_date': '2020-06-13T06:00:46.904000Z', 'tx_amount': 29627, 'tx_mode': 'Debit', 'tx_channel': 'mobile', 'bank_name': 'GBank', 'dob': ['1992-01-01 00:00:00']}
A5: ltuoawiob | B5: uuilawobmn | C5: {'tx_id': '5ed3d67b8723c11444c43283', 'tx_date': '2020-06-13T16:10:51.479000Z', 'tx_amount': 27791, 'tx_mode': 'Debit', 'tx_channel': 'web', 'bank_name': 'KBank', 'dob': ['1981-01-07 00:00:00']}
A6: nakuolo | B6: donald | C6: {'tx_id': '5ed3d67b8723c11444c43283', 'tx_date': '2020-06-13T05:28:47.543000Z', 'tx_amount': 6192, 'tx_mode': 'Debit', 'tx_channel': 'web', 'bank_name': 'QBank', 'dob': ['n/a']}
A7: juagn | B7: ahcnaiz | C7: {'tx_id': '5ed3d67b8723c11444c43283', 'tx_date': '2020-06-12T20:22:38.986000Z', 'tx_amount': 38445, 'tx_mode': 'Debit', 'tx_channel': 'mobile', 'bank_name': 'ABank', 'dob': ['1980-11-22 00:00:00']}
A8: eykeneowj | B8: ijutdh | C8: {'tx_id': '5ed3d67b8723c11444c43283', 'tx_date': '2020-06-13T06:00:46.904000Z', 'tx_amount': 29627, 'tx_mode': 'Debit', 'tx_channel': 'mobile', 'bank_name': 'GBank', 'dob': ['1998-08-20 00:00:00']}
A9: ellbo | B9: sasahn | C9: {'tx_id': '5ed3d67b8723c11444c43283', 'tx_date': '2020-06-13T16:10:51.479000Z', 'tx_amount': 27791, 'tx_mode': 'Debit', 'tx_channel': 'web', 'bank_name': 'KBank', 'dob': ['1976-12-12 00:00:00']}
A10: ooadelb | B10: ruktam | C10: {'tx_id': '5ed3d67b8723c11444c43283', 'tx_date': '2020-06-13T05:28:47.543000Z', 'tx_amount': 6192, 'tx_mode': 'Debit', 'tx_channel': 'web', 'bank_name': 'QBank', 'dob': ['1976-12-12 00:00:00']}
A11: ali | B11: grgniir kaeouakn | C11: {'tx_id': '5ed3d67b8723c11444c43283', 'tx_date': '2020-06-12T20:22:38.986000Z', 'tx_amount': 38445, 'tx_mode': 'Debit', 'tx_channel': 'mobile', 'bank_name': 'ABank', 'dob': ['n/a']}
A12: ial | B12: ubykua | C12: {'tx_id': '5ed3d67b8723c11444c43283', 'tx_date': '2020-06-13T06:00:46.904000Z', 'tx_amount': 29627, 'tx_mode': 'Debit', 'tx_channel': 'mobile', 'bank_name': 'GBank', 'dob': ['n/a']}
... A128: oin | B128: oedpum | C128: {'tx_id': '5ed3d67b8723c11444c43283', 'tx_date': '2020-06-13T06:00:46.904000Z', 'tx_amount': 29627, 'tx_mode': 'Debit', 'tx_channel': 'mobile', 'bank_name': 'GBank', 'dob': ['n/a']}

Sheet Cleaned Data
A1: Record ID | B1: First Name | C1: Last Name | D1: Full Name | E1: DOB | F1: Age | G1: Age Band | H1: Source Tx ID | I1: Tx Date | J1: Tx Time | K1: Tx Hour | L1: Tx Amount | M1: Tx Mode | N1: Tx Channel | O1: Bank | P1: Transaction Key
A2: 1 | B2: Nooeukw | C2: Uuoaklowalb | D2: Nooeukw Uuoaklowalb | E2: 1992-11-10 | F2: 28 | G2: Under 30 | H2: 5ed3d67b8723c11444c43283 | I2: 2020-06-13 | J2: 05:28:47 | K2: 5 | L2: 6192 | M2: Debit | N2: web | O2: QBank | P2: 2020-06-13|6192|QBank
A3: 2 | B3: Angulbo | C3: Seagn | D3: Angulbo Seagn | G3: Unknown | H3: 5ed3d67b8723c11444c43283 | I3: 2020-06-12 | J3: 20:22:38 | K3: 20 | L3: 38445 | M3: Debit | N3: mobile | O3: ABank | P3: 2020-06-12|38445|ABank
A4: 3 | B4: Dukowi | C4: Eukloomja | D4: Dukowi Eukloomja | E4: 1992-01-01 | F4: 28 | G4: Under 30 | H4: 5ed3d67b8723c11444c43283 | I4: 2020-06-13 | J4: 06:00:46 | K4: 6 | L4: 29627 | M4: Debit | N4: mobile | O4: GBank | P4: 2020-06-13|29627|GBank
A5: 4 | B5: Ltuoawiob | C5: Uuilawobmn | D5: Ltuoawiob Uuilawobmn | E5: 1981-01-07 | F5: 39 | G5: 30-39 | H5: 5ed3d67b8723c11444c43283 | I5: 2020-06-13 | J5: 16:10:51 | K5: 16 | L5: 27791 | M5: Debit | N5: web | O5: KBank | P5: 2020-06-13|27791|KBank
A6: 5 | B6: Nakuolo | C6: Donald | D6: Nakuolo Donald | G6: Unknown | H6: 5ed3d67b8723c11444c43283 | I6: 2020-06-13 | J6: 05:28:47 | K6: 5 | L6: 6192 | M6: Debit | N6: web | O6: QBank | P6: 2020-06-13|6192|QBank
A7: 6 | B7: Juagn | C7: Ahcnaiz | D7: Juagn Ahcnaiz | E7: 1980-11-22 | F7: 40 | G7: 40-49 | H7: 5ed3d67b8723c11444c43283 | I7: 2020-06-12 | J7: 20:22:38 | K7: 20 | L7: 38445 | M7: Debit | N7: mobile | O7: ABank | P7: 2020-06-12|38445|ABank
A8: 7 | B8: Eykeneowj | C8: Ijutdh | D8: Eykeneowj Ijutdh | E8: 1998-08-20 | F8: 22 | G8: Under 30 | H8: 5ed3d67b8723c11444c43283 | I8: 2020-06-13 | J8: 06:00:46 | K8: 6 | L8: 29627 | M8: Debit | N8: mobile | O8: GBank | P8: 2020-06-13|29627|GBank
A9: 8 | B9: Ellbo | C9: Sasahn | D9: Ellbo Sasahn | E9: 1976-12-12 | F9: 44 | G9: 40-49 | H9: 5ed3d67b8723c11444c43283 | I9: 2020-06-13 | J9: 16:10:51 | K9: 16 | L9: 27791 | M9: Debit | N9: web | O9: KBank | P9: 2020-06-13|27791|KBank
A10: 9 | B10: Ooadelb | C10: Ruktam | D10: Ooadelb Ruktam | E10: 1976-12-12 | F10: 44 | G10: 40-49 | H10: 5ed3d67b8723c11444c43283 | I10: 2020-06-13 | J10: 05:28:47 | K10: 5 | L10: 6192 | M10: Debit | N10: web | O10: QBank | P10: 2020-06-13|6192|QBank
A11: 10 | B11: Ali | C11: Grgniir Kaeouakn | D11: Ali Grgniir Kaeouakn | G11: Unknown | H11: 5ed3d67b8723c11444c43283 | I11: 2020-06-12 | J11: 20:22:38 | K11: 20 | L11: 38445 | M11: Debit | N11: mobile | O11: ABank | P11: 2020-06-12|38445|ABank
A12: 11 | B12: Ial | C12: Ubykua | D12: Ial Ubykua | G12: Unknown | H12: 5ed3d67b8723c11444c43283 | I12: 2020-06-13 | J12: 06:00:46 | K12: 6 | L12: 29627 | M12: Debit | N12: mobile | O12: GBank | P12: 2020-06-13|29627|GBank
A13: 12 | B13: Owjoloaur | C13: Eaoltse | D13: Owjoloaur Eaoltse | G13: Unknown | H13: 5ed3d67b8723c11444c43283 | I13: 2020-06-13 | J13: 16:10:51 | K13: 16 | L13: 27791 | M13: Debit | N13: web | O13: KBank | P13: 2020-06-13|27791|KBank
A14: 13 | B14: Boadigasm | C14: Hycknouwyeniu | D14: Boadigasm Hycknouwyeniu | G14: Unknown | H14: 5ed3d67b8723c11444c43283 | I14: 2020-06-13 | J14: 05:28:47 | K14: 5 | L14: 6192 | M14: Debit | N14: web | O14: QBank | P14: 2020-06-13|6192|QBank
A15: 14 | B15: Ywmuia | C15: Oaeuld Omyiosalnfula | D15: Ywmuia Oaeuld Omyiosalnfula | E15: 1984-06-13 | F15: 36 | G15: 30-39 | H15: 5ed3d67b8723c11444c43283 | I15: 2020-06-12 | J15: 20:22:38 | K15: 20 | L15: 38445 | M15: Debit | N15: mobile | O15: ABank | P15: 2020-06-12|38445|ABank
A16: 15 | B16: Owug | C16: Fuatas | D16: Owug Fuatas | G16: Unknown | H16: 5ed3d67b8723c11444c43283 | I16: 2020-06-13 | J16: 06:00:46 | K16: 6 | L16: 29627 | M16: Debit | N16: mobile | O16: GBank | P16: 2020-06-13|29627|GBank
A17: 16 | B17: Eaeodkg | C17: Nloadd | D17: Eaeodkg Nloadd | G17: Unknown | H17: 5ed3d67b8723c11444c43283 | I17: 2020-06-13 | J17: 16:10:51 | K17: 16 | L17: 27791 | M17: Debit | N17: web | O17: KBank | P17: 2020-06-13|27791|KBank
A18: 17 | B18: Adyuns | C18: Naczhai | D18: Adyuns Naczhai | G18: Unknown | H18: 5ed3d67b8723c11444c43283 | I18: 2020-06-13 | J18: 05:28:47 | K18: 5 | L18: 6192 | M18: Debit | N18: web | O18: QBank | P18: 2020-06-13|6192|QBank
A19: 18 | B19: Aiblnafoa | C19: Ollutoep | D19: Aiblnafoa Ollutoep | G19: Unknown | H19: 5ed3d67b8723c11444c43283 | I19: 2020-06-12 | J19: 20:22:38 | K19: 20 | L19: 38445 | M19: Debit | N19: mobile | O19: ABank | P19: 2020-06-12|38445|ABank
A20: 19 | B20: Dokeay | C20: Egesr Jmumoan | D20: Dokeay Egesr Jmumoan | G20: Unknown | H20: 5ed3d67b8723c11444c43283 | I20: 2020-06-13 | J20: 06:00:46 | K20: 6 | L20: 29627 | M20: Debit | N20: mobile | O20: GBank | P20: 2020-06-13|29627|GBank
A21: 20 | B21: E Okowuhoonw | C21: Izahbteel | D21: E Okowuhoonw Izahbteel | G21: Unknown | H21: 5ed3d67b8723c11444c43283 | I21: 2020-06-13 | J21: 16:10:51 | K21: 16 | L21: 27791 | M21: Debit | N21: web | O21: KBank | P21: 2020-06-13|27791|KBank
A22: 21 | B22: Imawinuk | C22: Iadmil | D22: Imawinuk Iadmil | G22: Unknown | H22: 5ed3d67b8723c11444c43283 | I22: 2020-06-13 | J22: 05:28:47 | K22: 5 | L22: 6192 | M22: Debit | N22: web | O22: QBank | P22: 2020-06-13|6192|QBank
A23: 22 | B23: Kroow | C23: Odqis | D23: Kroow Odqis | G23: Unknown | H23: 5ed3d67b8723c11444c43283 | I23: 2020-06-12 | J23: 20:22:38 | K23: 20 | L23: 38445 | M23: Debit | N23: mobile | O23: ABank | P23: 2020-06-12|38445|ABank
A24: 23 | B24: Oogbnslou | C24: Lezeeki | D24: Oogbnslou Lezeeki | E24: 1981-06-27 | F24: 39 | G24: 30-39 | H24: 5ed3d67b8723c11444c43283 | I24: 2020-06-13 | J24: 06:00:46 | K24: 6 | L24: 29627 | M24: Debit | N24: mobile | O24: GBank | P24: 2020-06-13|29627|GBank
A25: 24 | B25: Oujkn | C25: Aoiu Ulaleafdosmyoln | D25: Oujkn Aoiu Ulaleafdosmyoln | E25: 1989-12-29 | F25: 30 | G25: 30-39 | H25: 5ed3d67b8723c11444c43283 | I25: 2020-06-13 | J25: 16:10:51 | K25: 16 | L25: 27791 | M25: Debit | N25: web | O25: KBank | P25: 2020-06-13|27791|KBank
A26: 25 | B26: Aimuwy | C26: Measj | D26: Aimuwy Measj | E26: 1981-01-07 | F26: 39 | G26: 30-39 | H26: 5ed3d67b8723c11444c43283 | I26: 2020-06-13 | J26: 05:28:47 | K26: 5 | L26: 6192 | M26: Debit | N26: web | O26: QBank | P26: 2020-06-13|6192|QBank
A27: 26 | B27: Anygoeeldu | C27: Dllaamio | D27: Anygoeeldu Dllaamio | G27: Unknown | H27: 5ed3d67b8723c11444c43283 | I27: 2020-06-12 | J27: 20:22:38 | K27: 20 | L27: 38445 | M27: Debit | N27: mobile | O27: ABank | P27: 2020-06-12|38445|ABank
A28: 27 | B28: Uiwdo | C28: Audelb Mllooaialunof | D28: Uiwdo Audelb Mllooaialunof | G28: Unknown | H28: 5ed3d67b8723c11444c43283 | I28: 2020-06-13 | J28: 06:00:46 | K28: 6 | L28: 29627 | M28: Debit | N28: mobile | O28: GBank | P28: 2020-06-13|29627|GBank
A29: 28 | B29: Yaeikdno | C29: O Saederifaahbl | D29: Yaeikdno O Saederifaahbl | G29: Unknown | H29: 5ed3d67b8723c11444c43283 | I29: 2020-06-13 | J29: 16:10:51 | K29: 16 | L29: 27791 | M29: Debit | N29: web | O29: KBank | P29: 2020-06-13|27791|KBank
A30: 29 | B30: Joo | C30: Lexce | D30: Joo Lexce | E30: 1999-12-23 | F30: 20 | G30: Under 30 | H30: 5ed3d67b8723c11444c43283 | I30: 2020-06-13 | J30: 05:28:47 | K30: 5 | L30: 6192 | M30: Debit | N30: web | O30: QBank | P30: 2020-06-13|6192|QBank
A31: 30 | B31: Oyeewal | C31: Aimolewfu | D31: Oyeewal Aimolewfu | G31: Unknown | H31: 5ed3d67b8723c11444c43283 | I31: 2020-06-12 | J31: 20:22:38 | K31: 20 | L31: 38445 | M31: Debit | N31: mobile | O31: ABank | P31: 2020-06-12|38445|ABank
A32: 31 | B32: Kruehio | C32: Rni Oisaaubhbd | D32: Kruehio Rni Oisaaubhbd | G32: Unknown | H32: 5ed3d67b8723c11444c43283 | I32: 2020-06-13 | J32: 06:00:46 | K32: 6 | L32: 29627 | M32: Debit | N32: mobile | O32: GBank | P32: 2020-06-13|29627|GBank
A33: 32 | B33: Wounlraegob | C33: Urolmei | D33: Wounlraegob Urolmei | E33: 1979-09-27 | F33: 41 | G33: 40-49 | H33: 5ed3d67b8723c11444c43283 | I33: 2020-06-13 | J33: 16:10:51 | K33: 16 | L33: 27791 | M33: Debit | N33: web | O33: KBank | P33: 2020-06-13|27791|KBank
A34: 33 | B34: Ewneze | C34: Ibdhcmeu | D34: Ewneze Ibdhcmeu | G34: Unknown | H34: 5ed3d67b8723c11444c43283 | I34: 2020-06-13 | J34: 05:28:47 | K34: 5 | L34: 6192 | M34: Debit | N34: web | O34: QBank | P34: 2020-06-13|6192|QBank
A35: 34 | B35: Woknueo | C35: Oienalcr | D35: Woknueo Oienalcr | G35: Unknown | H35: 5ed3d67b8723c11444c43283 | I35: 2020-06-12 | J35: 20:22:38 | K35: 20 | L35: 38445 | M35: Debit | N35: mobile | O35: ABank | P35: 2020-06-12|38445|ABank
A36: 35 | B36: Bedriie | C36: Nsnkloyiaoa | D36: Bedriie Nsnkloyiaoa | G36: Unknown | H36: 5ed3d67b8723c11444c43283 | I36: 2020-06-13 | J36: 06:00:46 | K36: 6 | L36: 29627 | M36: Debit | N36: mobile | O36: GBank | P36: 2020-06-13|29627|GBank
A37: 36 | B37: Loeyowe | C37: Soqid | D37: Loeyowe Soqid | G37: Unknown | H37: 5ed3d67b8723c11444c43283 | I37: 2020-06-13 | J37: 16:10:51 | K37: 16 | L37: 27791 | M37: Debit | N37: web | O37: KBank | P37: 2020-06-13|27791|KBank
A38: 37 | B38: Auwngo | C38: Raenvcoi | D38: Auwngo Raenvcoi | G38: Unknown | H38: 5ed3d67b8723c11444c43283 | I38: 2020-06-13 | J38: 05:28:47 | K38: 5 | L38: 6192 | M38: Debit | N38: web | O38: QBank | P38: 2020-06-13|6192|QBank
A39: 38 | B39: Loognbosu | C39: Lsumea | D39: Loognbosu Lsumea | G39: Unknown | H39: 5ed3d67b8723c11444c43283 | I39: 2020-06-12 | J39: 20:22:38 | K39: 20 | L39: 38445 | M39: Debit | N39: mobile | O39: ABank | P39: 2020-06-12|38445|ABank
A40: 39 | B40: Eeciknh | C40: Uaanbeibdt | D40: Eeciknh Uaanbeibdt | G40: Unknown | H40: 5ed3d67b8723c11444c43283 | I40: 2020-06-13 | J40: 06:00:46 | K40: 6 | L40: 29627 | M40: Debit | N40: mobile | O40: GBank | P40: 2020-06-13|29627|GBank
...

Sheet Data Quality Log
A1: Data Quality Issues Found & Resolved
A2: Field | B2: Issue Found | C2: Rows Affected | D2: Action Taken
A3: first_name | B3: All values lower-case, no capitalisation | C3: 127 | D3: Trimmed whitespace, applied Title Case
A4: last_name | B4: All values lower-case, no capitalisation | C4: 127 | D4: Trimmed whitespace, applied Title Case
A5: tx_id | B5: Only 1 distinct value across all 127 rows - not a usable key | C5: 127 | D5: Retained as source_tx_id; added surrogate record_id 1..n
A6: tx_date | B6: ISO-8601 string with microseconds and Z suffix | C6: 127 | D6: Parsed to UTC datetime; split into tx_date / tx_time / tx_hour
A7: tx_amount | B7: 4 distinct amounts only; stored inside nested text | C7: 127 | D7: Extracted to numeric integer column
A8: tx_mode | B8: Zero variance - every row is 'Debit' | C8: 127 | D8: Kept but flagged: carries no analytical information
A9: dob | B9: Wrapped in a single-element list | C9: 127 | D9: Unwrapped to a scalar value
A10: dob | B10: Placeholder string 'n/a' used instead of a null | C10: 82 | D10: Converted to true NULL (missing, not imputed)
A11: age | B11: Not present in source | C11: 127 | D11: Derived from dob vs transaction date; NULL where dob missing
A12: transaction (whole payload) | B12: Only 4 unique date/amount/bank combinations repeated across 127 rows | C12: 123 | D12: Flagged. 4 distinct transactions identified; duplicates NOT deleted (each row has a unique customer)
A13: whole row | B13: Exact duplicate customer+transaction rows | C13: 0 | D13: None found - every row is a distinct customer
A15: Note: Rows shaded orange affect more than 50 records. Missing DOB values were left NULL rather than imputed, so any age-based figure below covers only the 45 records that have one.

Sheet Summary
A1: Summary Statistics
A3: Record counts
A4: Total records | B4: =COUNTA('Cleaned Data'!A2:A128) -> 127
A5: Distinct customers | B5: {=SUMPRODUCT(('Cleaned Data'!D2:D128<>"")/COUNTIF('Cleaned Data'!D2:D128,'Cleaned Data'!D2:D128&""))} -> 127
A6: Distinct transactions | B6: {=SUMPRODUCT(('Cleaned Data'!P2:P128<>"")/COUNTIF('Cleaned Data'!P2:P128,'Cleaned Data'!P2:P128&""))} -> 4
A7: Duplication rate (rows vs distinct tx) | B7: =1-B6/B4 -> 0.96850394
A9: Completeness
A10: Records with a DOB | B10: =COUNT('Cleaned Data'!F2:F128) -> 45
A11: Records missing a DOB | B11: =B4-B10 -> 82
A12: DOB completeness | B12: =B10/B4 -> 0.35433071
A14: Transaction values (as recorded, duplicates included)
A15: Sum of Tx Amount | B15: =SUM('Cleaned Data'!L2:L128) -> 3237969
A16: Average Tx Amount | B16: =AVERAGE('Cleaned Data'!L2:L128) -> 25495.819
A17: Minimum Tx Amount | B17: =MIN('Cleaned Data'!L2:L128) -> 6192
A18: Maximum Tx Amount | B18: =MAX('Cleaned Data'!L2:L128) -> 38445
A20: Channel Split
A21: Web records | B21: =COUNTIF('Cleaned Data'!N2:N128,"web") -> 63
A22: Mobile records | B22: =COUNTIF('Cleaned Data'!N2:N128,"mobile") -> 64
A23: Web value | B23: =SUMIF('Cleaned Data'!N2:N128,"web",'Cleaned Data'!L2:L128) -> 1059665
A24: Mobile value | B24: =SUMIF('Cleaned Data'!N2:N128,"mobile",'Cleaned Data'!L2:L128) -> 2178304
A26: Age (45 records with a DOB only)
A27: Average age | B27: =AVERAGE('Cleaned Data'!F2:F128) -> 33.2
A28: Youngest | B28: =MIN('Cleaned Data'!F2:F128) -> 20
A29: Oldest | B29: =MAX('Cleaned Data'!F2:F128) -> 53
A31: By bank
A32: Bank | B32: Records | C32: Value
A33: ABank | B33: =COUNTIF('Cleaned Data'!O2:O128,A33) -> 32 | C33: =SUMIF('Cleaned Data'!O2:O128,A33,'Cleaned Data'!L2:L128) -> 1230240
A34: GBank | B34: =COUNTIF('Cleaned Data'!O2:O128,A34) -> 32 | C34: =SUMIF('Cleaned Data'!O2:O128,A34,'Cleaned Data'!L2:L128) -> 948064
A35: KBank | B35: =COUNTIF('Cleaned Data'!O2:O128,A35) -> 31 | C35: =SUMIF('Cleaned Data'!O2:O128,A35,'Cleaned Data'!L2:L128) -> 861521
A36: QBank | B36: =COUNTIF('Cleaned Data'!O2:O128,A36) -> 32 | C36: =SUMIF('Cleaned Data'!O2:O128,A36,'Cleaned Data'!L2:L128) -> 198144

Sheet Dashboard
A1: Transaction Dashboard
A2: Total records | C2: Distinct transactions | E2: Total value | G2: Average value | I2: DOB completeness
A3: =COUNTA('Cleaned Data'!A2:A128) -> 127 | C3: {=SUMPRODUCT(('Cleaned Data'!P2:P128<>"")/COUNTIF('Cleaned Data'!P2:P128,'Cleaned Data'!P2:P128&""))} -> 4 | E3: =SUM('Cleaned Data'!L2:L128) -> 3237969 | G3: =AVERAGE('Cleaned Data'!L2:L128) -> 25495.819 | I3: =COUNT('Cleaned Data'!F2:F128)/COUNTA('Cleaned Data'!A2:A128) -> 0.35433071
K5: Bank | L5: Records | M5: Value | O5: Tx Hour | P5: Records | Q5: Hour (num)
K6: ABank | L6: =COUNTIF('Cleaned Data'!$O$2:$O$128,$K6) -> 32 | M6: =SUMIF('Cleaned Data'!$O$2:$O$128,$K6,'Cleaned Data'!$L$2:$L$128) -> 1230240 | O6: =TEXT($Q6,"00")&":00" -> 05:00 | P6: =COUNTIF('Cleaned Data'!$K$2:$K$128,$Q6) -> 32 | Q6: 5
K7: GBank | L7: =COUNTIF('Cleaned Data'!$O$2:$O$128,$K7) -> 32 | M7: =SUMIF('Cleaned Data'!$O$2:$O$128,$K7,'Cleaned Data'!$L$2:$L$128) -> 948064 | O7: =TEXT($Q7,"00")&":00" -> 06:00 | P7: =COUNTIF('Cleaned Data'!$K$2:$K$128,$Q7) -> 32 | Q7: =Q6+1 -> 6
K8: KBank | L8: =COUNTIF('Cleaned Data'!$O$2:$O$128,$K8) -> 31 | M8: =SUMIF('Cleaned Data'!$O$2:$O$128,$K8,'Cleaned Data'!$L$2:$L$128) -> 861521 | O8: =TEXT($Q8,"00")&":00" -> 07:00 | P8: =COUNTIF('Cleaned Data'!$K$2:$K$128,$Q8) -> 0 | Q8: =Q7+1 -> 7
K9: QBank | L9: =COUNTIF('Cleaned Data'!$O$2:$O$128,$K9) -> 32 | M9: =SUMIF('Cleaned Data'!$O$2:$O$128,$K9,'Cleaned Data'!$L$2:$L$128) -> 198144 | O9: =TEXT($Q9,"00")&":00" -> 08:00 | P9: =COUNTIF('Cleaned Data'!$K$2:$K$128,$Q9) -> 0 | Q9: =Q8+1 -> 8
O10: =TEXT($Q10,"00")&":00" -> 09:00 | P10: =COUNTIF('Cleaned Data'!$K$2:$K$128,$Q10) -> 0 | Q10: =Q9+1 -> 9
K11: Channel | L11: Value | M11: Records | O11: =TEXT($Q11,"00")&":00" -> 10:00 | P11: =COUNTIF('Cleaned Data'!$K$2:$K$128,$Q11) -> 0 | Q11: =Q10+1 -> 10
K12: web | L12: =SUMIF('Cleaned Data'!$N$2:$N$128,$K12,'Cleaned Data'!$L$2:$L$128) -> 1059665 | M12: =COUNTIF('Cleaned Data'!$N$2:$N$128,$K12) -> 63 | O12: =TEXT($Q12,"00")&":00" -> 11:00 | P12: =COUNTIF('Cleaned Data'!$K$2:$K$128,$Q12) -> 0 | Q12: =Q11+1 -> 11
K13: mobile | L13: =SUMIF('Cleaned Data'!$N$2:$N$128,$K13,'Cleaned Data'!$L$2:$L$128) -> 2178304 | M13: =COUNTIF('Cleaned Data'!$N$2:$N$128,$K13) -> 64 | O13: =TEXT($Q13,"00")&":00" -> 12:00 | P13: =COUNTIF('Cleaned Data'!$K$2:$K$128,$Q13) -> 0 | Q13: =Q12+1 -> 12
O14: =TEXT($Q14,"00")&":00" -> 13:00 | P14: =COUNTIF('Cleaned Data'!$K$2:$K$128,$Q14) -> 0 | Q14: =Q13+1 -> 13
K15: Age Band | L15: Records | O15: =TEXT($Q15,"00")&":00" -> 14:00 | P15: =COUNTIF('Cleaned Data'!$K$2:$K$128,$Q15) -> 0 | Q15: =Q14+1 -> 14
K16: Under 30 | L16: =COUNTIF('Cleaned Data'!$G$2:$G$128,$K16) -> 19 | O16: =TEXT($Q16,"00")&":00" -> 15:00 | P16: =COUNTIF('Cleaned Data'!$K$2:$K$128,$Q16) -> 0 | Q16: =Q15+1 -> 15
K17: 30-39 | L17: =COUNTIF('Cleaned Data'!$G$2:$G$128,$K17) -> 12 | O17: =TEXT($Q17,"00")&":00" -> 16:00 | P17: =COUNTIF('Cleaned Data'!$K$2:$K$128,$Q17) -> 31 | Q17: =Q16+1 -> 16
K18: 40-49 | L18: =COUNTIF('Cleaned Data'!$G$2:$G$128,$K18) -> 12 | O18: =TEXT($Q18,"00")&":00" -> 17:00 | P18: =COUNTIF('Cleaned Data'!$K$2:$K$128,$Q18) -> 0 | Q18: =Q17+1 -> 17
K19: 50+ | L19: =COUNTIF('Cleaned Data'!$G$2:$G$128,$K19) -> 2 | O19: =TEXT($Q19,"00")&":00" -> 18:00 | P19: =COUNTIF('Cleaned Data'!$K$2:$K$128,$Q19) -> 0 | Q19: =Q18+1 -> 18
K20: Unknown | L20: =COUNTIF('Cleaned Data'!$G$2:$G$128,$K20) -> 82 | O20: =TEXT($Q20,"00")&":00" -> 19:00 | P20: =COUNTIF('Cleaned Data'!$K$2:$K$128,$Q20) -> 0 | Q20: =Q19+1 -> 19
O21: =TEXT($Q21,"00")&":00" -> 20:00 | P21: =COUNTIF('Cleaned Data'!$K$2:$K$128,$Q21) -> 32 | Q21: =Q20+1 -> 20
